<?xml version="1.0" ?>
<robot name="quadruped_test">

<!-- Base -->
  <link name="base_link">
    <inertial>
      <origin rpy="0 0 0" xyz="0 0 0"/>
      <mass value="0.1"/>
      <inertia ixx="0.1" ixy="0" ixz="0" iyy="0.1" iyz="0" izz="0.1"/>
    </inertial>
  </link>
  <joint name="add_height_joint" type="fixed">
    <!-- <origin rpy="0 0 0" xyz="0 0 0"/> -->
    <parent link="base_link"/>
    <child link="chassis_link"/>
    <origin rpy="0 0 0" xyz="0 0 0.8"/>
  </joint>

<!-- chassis -->
  <link name="chassis_link">
    <visual>
      <geometry>
        <box size=".226 0.16 .07"/>
      </geometry>
      <material name="black">
        <color rgba="0 0 0 1"/>
      </material>
    </visual>
    <collision>
      <geometry>
       <box size=".226 0.16 .07"/>
      </geometry>
    </collision>
    <inertial>
      <origin rpy="0 0 0" xyz="0 0 0"/>
      <mass value="3.2"/>
      <inertia ixx="1.0" ixy="0.0" ixz="0.0" iyy="1.0" iyz="0.0" izz="1.0"/>
    </inertial>
  </link>

<!-- front_left -->
  <joint name="base_to_upper_leg_front_left" type="revolute">
    <axis xyz="0 1 0"/>
    <parent link="chassis_link"/>
    <child link="upper_leg_front_left_link"/>
    <origin xyz="0.113 0.08 -0.06" rpy="0.0 0.5 0"/>
    <limit effort="100" velocity="100"/>
    <joint_properties damping="0.0" friction="0.0"/>
  </joint>

  <link name="upper_leg_front_left_link">
    <visual>
      <geometry>
        <box size=".02 0.02 .12"/>
      </geometry>
      <material name="grey">
        <color rgba="0.65 0.65 0.75 1"/>
      </material>
    </visual>
    <collision>
      <geometry>
        <box size=".02 0.02 .12"/>
      </geometry>
    </collision>
    <inertial>
      <mass value="0.05"/>
      <inertia ixx="1.0" ixy="0.0" ixz="0.0" iyy="1.0" iyz="0.0" izz="1.0"/>
    </inertial>
  </link>


</robot>